Workbook

Sheet building_energy_data
A1: Timestamp | B1: Building_ID | C1: Energy_Usage (kWh) | D1: External Temperature (°F) | E1: Demand | F1: Humidity (%) | G1: Building_Type | H1: Occupancy_Level
A2: 45658 | B2: B001 | C2: 121.3 | D2: 19.04 | E2: Normal | F2: 79.36 | G2: Industrial | H2: Low
A3: 45658.042 | B3: B001 | C3: 230.76 | D3: 54.72 | E3: Normal | F3: 80.37 | G3: Industrial | H3: High
A4: 45658.083 | B4: B001 | C4: 187.21 | D4: 29.61 | E4: Normal | F4: 37.74 | G4: Industrial | H4: High
A5: 45658.125 | B5: B001 | C5: 262.23 | D5: 32.43 | E5: Normal | F5: 39.97 | G5: Industrial | H5: High
A6: 45658.167 | B6: B001 | C6: 472.97 | D6: 41.79 | E6: Normal | F6: 89.29 | G6: Industrial | H6: Medium
A7: 45658.208 | B7: B001 | C7: 198.15 | D7: 18.25 | E7: Normal | F7: 57.01 | G7: Industrial | H7: Medium
A8: 45658.25 | B8: B001 | C8: 369.35 | D8: 93.69 | E8: High Demand | F8: 33.01 | G8: Industrial | H8: Low
A9: 45658.292 | B9: B001 | C9: 374.21 | D9: 36.82 | E9: Normal | F9: 41.06 | G9: Industrial | H9: Low
A10: 45658.333 | B10: B001 | C10: 85.65 | D10: 17.82 | E10: Normal | F10: 31.17 | G10: Industrial | H10: Medium
A11: 45658.375 | B11: B001 | C11: 260.47 | D11: 63.09 | E11: Normal | F11: 55.7 | G11: Industrial | H11: High
A12: 45658.417 | B12: B001 | C12: 180.61 | D12: 59.52 | E12: Normal | F12: 36.72 | G12: Industrial | H12: Low
A13: 45658.458 | B13: B001 | C13: 305.79 | D13: 78.15 | E13: Normal | F13: 89.2 | G13: Industrial | H13: Medium
... A7201: 45672.958 | B7201: B020 | C7201: 137.5 | D7201: 82.22 | E7201: Normal | F7201: 46.03 | G7201: Residential | H7201: Medium

Sheet Energy Insights Dashboard
A1: 🔋 Building Energy Insights Dashboard
A3: 📊 Data Summary
A4: Total Records | B4: 7200
A5: Buildings Monitored | B5: 20
A6: Building Types | B6: 4
A7: Time Period | B7: Jan 1-15, 2025
A8: Data Frequency | B8: Hourly
A10: 📈 Insight 1: Average Energy Usage by Building Type
A11: Building Type | B11: Avg Energy (kWh) | C11: Total Energy (kWh)
A12: Industrial | B12: =AVERAGEIF(building_energy_data!G:G,A12,building_energy_data!C:C) -> 272.7232 | C12: =SUMIF(building_energy_data!G:G,A12,building_energy_data!C:C) -> 589082.11
A13: Residential | B13: =AVERAGEIF(building_energy_data!G:G,A13,building_energy_data!C:C) -> 285.54943 | C13: =SUMIF(building_energy_data!G:G,A13,building_energy_data!C:C) -> 411191.18
A14: Commercial | B14: =AVERAGEIF(building_energy_data!G:G,A14,building_energy_data!C:C) -> 279.02611 | C14: =SUMIF(building_energy_data!G:G,A14,building_energy_data!C:C) -> 502247
A15: Educational | B15: =AVERAGEIF(building_energy_data!G:G,A15,building_energy_data!C:C) -> 276.7429 | C15: =SUMIF(building_energy_data!G:G,A15,building_energy_data!C:C) -> 498137.22
A17: ⚡ Insight 2: High Demand Events Analysis
A18: Metric | B18: Count | C18: Percentage
A19: Normal Demand | B19: =COUNTIF(building_energy_data!E:E,"Normal") -> 6300 | C19: =B19/B21 -> 0.875
A20: High Demand | B20: =COUNTIF(building_energy_data!E:E,"*High Demand*") -> 900 | C20: =B20/B21 -> 0.125
A21: Total Events | B21: =B19+B20 -> 7200 | C21: 1
A23: 🏢 Insight 3: Energy Usage by Occupancy Level
A24: Occupancy Level | B24: Avg Energy (kWh)
A25: Low | B25: =AVERAGEIF(building_energy_data!H:H,A25,building_energy_data!C:C) -> 279.60759
A26: Medium | B26: =AVERAGEIF(building_energy_data!H:H,A26,building_energy_data!C:C) -> 275.92576
A27: High | B27: =AVERAGEIF(building_energy_data!H:H,A27,building_energy_data!C:C) -> 278.01267
A29: 🏆 Insight 4: Top 5 Energy Consuming Buildings
A30: Rank | B30: Building ID | C30: Total Energy (kWh) | E30: Building | F30: Total
A31: 1 | B31: =INDEX($E$31:$E$50,MATCH(C31,$F$31:$F$50,0)) -> B014 | C31: =LARGE($F$31:$F$50,1) -> 103663.54 | E31: B001 | F31: =SUMIF(building_energy_data!B:B,E31,building_energy_data!C:C) -> 95560.95
A32: 2 | B32: =INDEX($E$31:$E$50,MATCH(C32,$F$31:$F$50,0)) -> B008 | C32: =LARGE($F$31:$F$50,2) -> 103135.37 | E32: B002 | F32: =SUMIF(building_energy_data!B:B,E32,building_energy_data!C:C) -> 102672.52
A33: 3 | B33: =INDEX($E$31:$E$50,MATCH(C33,$F$31:$F$50,0)) -> B002 | C33: =LARGE($F$31:$F$50,3) -> 102672.52 | E33: B003 | F33: =SUMIF(building_energy_data!B:B,E33,building_energy_data!C:C) -> 98027.94
A34: 4 | B34: =INDEX($E$31:$E$50,MATCH(C34,$F$31:$F$50,0)) -> B009 | C34: =LARGE($F$31:$F$50,4) -> 102214.57 | E34: B004 | F34: =SUMIF(building_energy_data!B:B,E34,building_energy_data!C:C) -> 97043.78
A35: 5 | B35: =INDEX($E$31:$E$50,MATCH(C35,$F$31:$F$50,0)) -> B015 | C35: =LARGE($F$31:$F$50,5) -> 102083.78 | E35: B005 | F35: =SUMIF(building_energy_data!B:B,E35,building_energy_data!C:C) -> 98938.54
E36: B006 | F36: =SUMIF(building_energy_data!B:B,E36,building_energy_data!C:C) -> 97068.87
A37: 🌡️ Insight 5: Temperature vs Energy Correlation
A38: Temperature Range | B38: Avg Energy (kWh) | C38: Record Count | E38: B008 | F38: =SUMIF(building_energy_data!B:B,E38,building_energy_data!C:C) -> 103135.37
A39: Cold (<40°F) | B39: =AVERAGEIFS(building_energy_data!C:C,building_energy_data!D:D,"<40") -> 276.23525 | C39: =COUNTIFS(building_energy_data!D:D,"<40") -> 2337 | E39: B009 | F39: =SUMIF(building_energy_data!B:B,E39,building_energy_data!C:C) -> 102214.57
A40: Cool (40-60°F) | B40: =AVERAGEIFS(building_energy_data!C:C,building_energy_data!D:D,">=40",building_energy_data!D:D,"<60") -> 278.65709 | C40: =COUNTIFS(building_energy_data!D:D,">=40",building_energy_data!D:D,"<60") -> 1725 | E40: B010 | F40: =SUMIF(building_energy_data!B:B,E40,building_energy_data!C:C) -> 101476.33
A41: Moderate (60-75°F) | B41: =AVERAGEIFS(building_energy_data!C:C,building_energy_data!D:D,">=60",building_energy_data!D:D,"<75") -> 277.45759 | C41: =COUNTIFS(building_energy_data!D:D,">=60",building_energy_data!D:D,"<75") -> 1353 | E41: B011 | F41: =SUMIF(building_energy_data!B:B,E41,building_energy_data!C:C) -> 99359.19
A42: Warm (75-85°F) | B42: =AVERAGEIFS(building_energy_data!C:C,building_energy_data!D:D,">=75",building_energy_data!D:D,"<85") -> 274.58437 | C42: =COUNTIFS(building_energy_data!D:D,">=75",building_energy_data!D:D,"<85") -> 885 | E42: B012 | F42: =SUMIF(building_energy_data!B:B,E42,building_energy_data!C:C) -> 100411.05
A43: Hot (>85°F) | B43: =AVERAGEIFS(building_energy_data!C:C,building_energy_data!D:D,">=85") -> 284.44997 | C43: =COUNTIFS(building_energy_data!D:D,">=85") -> 900 | E43: B013 | F43: =SUMIF(building_energy_data!B:B,E43,building_energy_data!C:C) -> 101395.11
E44: B014 | F44: =SUMIF(building_energy_data!B:B,E44,building_energy_data!C:C) -> 103663.54
A45: 📋 Key Findings Summary | E45: B015 | F45: =SUMIF(building_energy_data!B:B,E45,building_energy_data!C:C) -> 102083.78
...

Sheet Statistical Report
A1: 📊 Statistical Summary Report
A3: Metric | B3: Energy Usage (kWh) | C3: Temperature (°F) | D3: Humidity (%)
A4: Mean | B4: =AVERAGE(building_energy_data!C:C) -> 277.8691 | C4: =AVERAGE(building_energy_data!D:D) -> 54.411418 | D4: =AVERAGE(building_energy_data!F:F) -> 59.826208
A5: Standard Deviation | B5: =_xlfn.STDEV.S(building_energy_data!C:C) -> 129.69386 | C5: =_xlfn.STDEV.S(building_energy_data!D:D) -> 23.460593 | D5: =_xlfn.STDEV.S(building_energy_data!F:F) -> 17.275891
A6: Median | B6: =MEDIAN(building_energy_data!C:C) -> 279.41 | C6: =MEDIAN(building_energy_data!D:D) -> 54.59 | D6: =MEDIAN(building_energy_data!F:F) -> 59.67
A7: Minimum | B7: =MIN(building_energy_data!C:C) -> 50.05 | C7: =MIN(building_energy_data!D:D) -> 14.02 | D7: =MIN(building_energy_data!F:F) -> 30
A8: Maximum | B8: =MAX(building_energy_data!C:C) -> 499.92 | C8: =MAX(building_energy_data!D:D) -> 95 | D8: =MAX(building_energy_data!F:F) -> 89.99
A10: 📋 Data Source Information
A11: Source Sheet: | B11: building_energy_data
A12: Total Records: | B12: =COUNTA(building_energy_data!A:A)-1 -> 7200
A14: 📊 Statistics by Building Type
A15: ⚡ Energy Usage (kWh)
A16: Building Type | B16: Mean | C16: Std Dev | D16: Median | E16: Min | F16: Max
A17: Industrial | B17: =AVERAGEIF(building_energy_data!G:G,"Industrial",building_energy_data!C:C) -> 272.7232 | C17: {=_xlfn.STDEV.S(IF(building_energy_data!G:G="Industrial",building_energy_data!C:C))} -> 129.24212 | D17: {=MEDIAN(IF(building_energy_data!G:G="Industrial",building_energy_data!C:C))} -> 273.455 | E17: =_xlfn.MINIFS(building_energy_data!C:C,building_energy_data!G:G,"Industrial") -> 50.08 | F17: =_xlfn.MAXIFS(building_energy_data!C:C,building_energy_data!G:G,"Industrial") -> 499.92
A18: Residential | B18: =AVERAGEIF(building_energy_data!G:G,"Residential",building_energy_data!C:C) -> 285.54943 | C18: {=_xlfn.STDEV.S(IF(building_energy_data!G:G="Residential",building_energy_data!C:C))} -> 130.72466 | D18: {=MEDIAN(IF(building_energy_data!G:G="Residential",building_energy_data!C:C))} -> 290.065 | E18: =_xlfn.MINIFS(building_energy_data!C:C,building_energy_data!G:G,"Residential") -> 50.32 | F18: =_xlfn.MAXIFS(building_energy_data!C:C,building_energy_data!G:G,"Residential") -> 499.52
A19: Commercial | B19: =AVERAGEIF(building_energy_data!G:G,"Commercial",building_energy_data!C:C) -> 279.02611 | C19: {=_xlfn.STDEV.S(IF(building_energy_data!G:G="Commercial",building_energy_data!C:C))} -> 128.68688 | D19: {=MEDIAN(IF(building_energy_data!G:G="Commercial",building_energy_data!C:C))} -> 278.87 | E19: =_xlfn.MINIFS(building_energy_data!C:C,building_energy_data!G:G,"Commercial") -> 50.52 | F19: =_xlfn.MAXIFS(building_energy_data!C:C,building_energy_data!G:G,"Commercial") -> 499.85
A20: Educational | B20: =AVERAGEIF(building_energy_data!G:G,"Educational",building_energy_data!C:C) -> 276.7429 | C20: {=_xlfn.STDEV.S(IF(building_energy_data!G:G="Educational",building_energy_data!C:C))} -> 130.20281 | D20: {=MEDIAN(IF(building_energy_data!G:G="Educational",building_energy_data!C:C))} -> 276.285 | E20: =_xlfn.MINIFS(building_energy_data!C:C,building_energy_data!G:G,"Educational") -> 50.05 | F20: =_xlfn.MAXIFS(building_energy_data!C:C,building_energy_data!G:G,"Educational") -> 499.51
A22: 🌡️ Temperature (°F)
A23: Building Type | B23: Mean | C23: Std Dev | D23: Median | E23: Min | F23: Max
A24: Industrial | B24: =AVERAGEIF(building_energy_data!G:G,"Industrial",building_energy_data!D:D) -> 54.420162 | C24: {=_xlfn.STDEV.S(IF(building_energy_data!G:G="Industrial",building_energy_data!D:D))} -> 23.732468 | D24: {=MEDIAN(IF(building_energy_data!G:G="Industrial",building_energy_data!D:D))} -> 54.555 | E24: =_xlfn.MINIFS(building_energy_data!D:D,building_energy_data!G:G,"Industrial") -> 14.04 | F24: =_xlfn.MAXIFS(building_energy_data!D:D,building_energy_data!G:G,"Industrial") -> 95
A25: Residential | B25: =AVERAGEIF(building_energy_data!G:G,"Residential",building_energy_data!D:D) -> 54.557701 | C25: {=_xlfn.STDEV.S(IF(building_energy_data!G:G="Residential",building_energy_data!D:D))} -> 23.015179 | D25: {=MEDIAN(IF(building_energy_data!G:G="Residential",building_energy_data!D:D))} -> 55.07 | E25: =_xlfn.MINIFS(building_energy_data!D:D,building_energy_data!G:G,"Residential") -> 14.04 | F25: =_xlfn.MAXIFS(building_energy_data!D:D,building_energy_data!G:G,"Residential") -> 94.91
A26: Commercial | B26: =AVERAGEIF(building_energy_data!G:G,"Commercial",building_energy_data!D:D) -> 54.562767 | C26: {=_xlfn.STDEV.S(IF(building_energy_data!G:G="Commercial",building_energy_data!D:D))} -> 23.233045 | D26: {=MEDIAN(IF(building_energy_data!G:G="Commercial",building_energy_data!D:D))} -> 54.04 | E26: =_xlfn.MINIFS(building_energy_data!D:D,building_energy_data!G:G,"Commercial") -> 14.07 | F26: =_xlfn.MAXIFS(building_energy_data!D:D,building_energy_data!G:G,"Commercial") -> 94.96
A27: Educational | B27: =AVERAGEIF(building_energy_data!G:G,"Educational",building_energy_data!D:D) -> 54.13255 | C27: {=_xlfn.STDEV.S(IF(building_energy_data!G:G="Educational",building_energy_data!D:D))} -> 23.727298 | D27: {=MEDIAN(IF(building_energy_data!G:G="Educational",building_energy_data!D:D))} -> 54.885 | E27: =_xlfn.MINIFS(building_energy_data!D:D,building_energy_data!G:G,"Educational") -> 14.02 | F27: =_xlfn.MAXIFS(building_energy_data!D:D,building_energy_data!G:G,"Educational") -> 94.91
A29: 💧 Humidity (%)
A30: Building Type | B30: Mean | C30: Std Dev | D30: Median | E30: Min | F30: Max
A31: Industrial | B31: =AVERAGEIF(building_energy_data!G:G,"Industrial",building_energy_data!F:F) -> 59.694556 | C31: {=_xlfn.STDEV.S(IF(building_energy_data!G:G="Industrial",building_energy_data!F:F))} -> 17.505572 | D31: {=MEDIAN(IF(building_energy_data!G:G="Industrial",building_energy_data!F:F))} -> 59.84 | E31: =_xlfn.MINIFS(building_energy_data!F:F,building_energy_data!G:G,"Industrial") -> 30.04 | F31: =_xlfn.MAXIFS(building_energy_data!F:F,building_energy_data!G:G,"Industrial") -> 89.99
A32: Residential | B32: =AVERAGEIF(building_energy_data!G:G,"Residential",building_energy_data!F:F) -> 59.985951 | C32: {=_xlfn.STDEV.S(IF(building_energy_data!G:G="Residential",building_energy_data!F:F))} -> 16.9828 | D32: {=MEDIAN(IF(building_energy_data!G:G="Residential",building_energy_data!F:F))} -> 59.735 | E32: =_xlfn.MINIFS(building_energy_data!F:F,building_energy_data!G:G,"Residential") -> 30.01 | F32: =_xlfn.MAXIFS(building_energy_data!F:F,building_energy_data!G:G,"Residential") -> 89.95
A33: Commercial | B33: =AVERAGEIF(building_energy_data!G:G,"Commercial",building_energy_data!F:F) -> 60.045928 | C33: {=_xlfn.STDEV.S(IF(building_energy_data!G:G="Commercial",building_energy_data!F:F))} -> 17.255236 | D33: {=MEDIAN(IF(building_energy_data!G:G="Commercial",building_energy_data!F:F))} -> 59.425 | E33: =_xlfn.MINIFS(building_energy_data!F:F,building_energy_data!G:G,"Commercial") -> 30 | F33: =_xlfn.MAXIFS(building_energy_data!F:F,building_energy_data!G:G,"Commercial") -> 89.99
A34: Educational | B34: =AVERAGEIF(building_energy_data!G:G,"Educational",building_energy_data!F:F) -> 59.636678 | C34: {=_xlfn.STDEV.S(IF(building_energy_data!G:G="Educational",building_energy_data!F:F))} -> 17.262277 | D34: {=MEDIAN(IF(building_energy_data!G:G="Educational",building_energy_data!F:F))} -> 59.68 | E34: =_xlfn.MINIFS(building_energy_data!F:F,building_energy_data!G:G,"Educational") -> 30 | F34: =_xlfn.MAXIFS(building_energy_data!F:F,building_energy_data!G:G,"Educational") -> 89.99

Sheet Anomaly Analysis
A1: ⚠️ Energy Anomaly Detection Analysis
A3: 📊 Anomaly Summary - Issues Identified
A4: Issue Type | B4: Count
A5: Low Occupancy + High Energy (>450 kWh) | B5: 288
A6: Nighttime High Energy (12am-5am, >450 kWh) | B6: 218
A7: Normal Temp + High Energy (60-75°F, >450 kWh) | B7: 149
A9: 🏢 Buildings with Most Anomalies (Low Occupancy + >400 kWh) | F9: ⏰ Hourly High Energy Events (>400 kWh)
A10: Building ID | B10: Anomaly Count | C10: Avg Anomaly (kWh) | D10: Max Anomaly (kWh) | F10: Hour | G10: Count
A11: B008 | B11: 40 | C11: 458 | D11: 497.8 | F11: 0 | G11: 66
A12: B010 | B12: 40 | C12: 451.9 | D12: 497.1 | F12: 0.041666667 | G12: 69
A13: B017 | B13: 37 | C13: 448.4 | D13: 495.9 | F13: 0.083333333 | G13: 68
A14: B002 | B14: 32 | C14: 435.1 | D14: 497.6 | F14: 0.125 | G14: 63
A15: B006 | B15: 31 | C15: 453.5 | D15: 499.2 | F15: 0.16666667 | G15: 65
A16: B009 | B16: 30 | C16: 451.4 | D16: 494.4 | F16: 0.20833333 | G16: 69
A17: B013 | B17: 30 | C17: 454.2 | D17: 499.2 | F17: 0.25 | G17: 68
A18: B003 | B18: 29 | C18: 444.8 | D18: 491.9 | F18: 0.29166667 | G18: 72
A19: B016 | B19: 29 | C19: 443.6 | D19: 499.5 | F19: 0.33333333 | G19: 61
A20: B007 | B20: 28 | C20: 455.4 | D20: 499.9 | F20: 0.375 | G20: 63
F21: 0.41666667 | G21: 66
A22: 🔍 Key Findings & Recommendations | F22: 0.45833333 | G22: 69
F23: 0.5 | G23: 66
A24: 🚨 288 instances of HIGH energy during LOW occupancy - equipment waste or malfunction | F24: 0.54166667 | G24: 65
A25: 🌙 218 high-energy events during nighttime (12am-5am) - investigate after-hours equipment | F25: 0.58333333 | G25: 69
A26: 🌡️ 149 high-energy events during moderate temps (60-75°F) - no HVAC justification | F26: 0.625 | G26: 70
A27: 🏢 B008 and B010 have MOST anomalies (40 each) - priority investigation needed | F27: 0.66666667 | G27: 68
A28: ⏰ Peak anomaly hour is 10 PM (82 events) - possible scheduling/automation issues | F28: 0.70833333 | G28: 75
A29: ⬇️ Lowest anomaly hour is 6 PM (48 events) - when occupants are leaving | F29: 0.75 | G29: 48
A30: 💡 RECOMMENDATION: Audit B008, B010, B017 for equipment malfunctions | F30: 0.79166667 | G30: 68
F31: 0.83333333 | G31: 75
F32: 0.875 | G32: 70
F33: 0.91666667 | G33: 82
F34: 0.95833333 | G34: 71
